Workbook

Sheet Resumen
A1: Centro de Tutorías - Modelo financiero y dashboard
A2: Caso base editable. Construido con documentación de Notion, fuentes de mercado y supuestos explícitos.
A4: KPI | B4: Caso base | D4: Decisión | E4: Lectura ejecutiva | G4: Mes | H4: Ingresos | I4: EBITDA
A5: Precio ponderado / hora | B5: =Unit_Economics!C5 | D5: Precio | E5: El precio objetivo es premium frente a alternativas locales; debe venderse con diagnóstico, tutores calificados y reportes de avance. | G5: =Forecast_Base!B$4 | H5: =Forecast_Base!B$9 | I5: =Forecast_Base!B$17
A6: Contribución / hora | B6: =Unit_Economics!C9 | D6: Rentabilidad | E6: El modelo funciona por contribución por hora. Con la mezcla base, cada hora aporta cerca del 25% después de tutor, cobros y materiales. | G6: =Forecast_Base!C$4 | H6: =Forecast_Base!C$9 | I6: =Forecast_Base!C$17
A7: Alumnos para break-even | B7: =Unit_Economics!C16 | D7: Punto de equilibrio | E7: La meta crítica es superar el umbral de alumnos activos mensuales y sostener horas recurrentes. | G7: =Forecast_Base!D$4 | H7: =Forecast_Base!D$9 | I7: =Forecast_Base!D$17
A8: Mes EBITDA positivo | B8: =INDEX(Forecast_Base!$B$4:$Y$4,1,MATCH(TRUE,Forecast_Base!$B$17:$Y$17>0,0)) | D8: Marketing | E8: La pauta base de USD 400/mes está dentro del rango recomendado en Notion; debe optimizarse por CPL y conversión en WhatsApp. | G8: =Forecast_Base!E$4 | H8: =Forecast_Base!E$9 | I8: =Forecast_Base!E$17
A9: Mes recuperación inversión | B9: =IFERROR(INDEX(Forecast_Base!$B$4:$Y$4,1,MATCH(TRUE,Forecast_Base!$B$19:$Y$19>0,0)),"No en 24m") | D9: Operación | E9: La calidad de tutores y seguimiento a padres reducen churn y sostienen la posibilidad de cobrar premium. | G9: =Forecast_Base!F$4 | H9: =Forecast_Base!F$9 | I9: =Forecast_Base!F$17
A10: Ingresos mes 12 | B10: =Forecast_Base!M9 | D10: Capital | E10: Conviene iniciar con inversión inicial más dos meses de costos fijos para no cortar aprendizaje de campañas demasiado pronto. | G10: =Forecast_Base!G$4 | H10: =Forecast_Base!G$9 | I10: =Forecast_Base!G$17
A11: EBITDA mes 12 | B11: =Forecast_Base!M17 | D11: Siguiente paso | E11: Usar los primeros 30 días para medir CPL real, conversión lead-cliente, horas promedio por alumno y retención. | G11: =Forecast_Base!H$4 | H11: =Forecast_Base!H$9 | I11: =Forecast_Base!H$17
G12: =Forecast_Base!I$4 | H12: =Forecast_Base!I$9 | I12: =Forecast_Base!I$17
G13: =Forecast_Base!J$4 | H13: =Forecast_Base!J$9 | I13: =Forecast_Base!J$17
A14: Mes | B14: Flujo acumulado | C14: Break-even | G14: =Forecast_Base!K$4 | H14: =Forecast_Base!K$9 | I14: =Forecast_Base!K$17
A15: =Forecast_Base!B$4 | B15: =Forecast_Base!B$19 | C15: =0 | G15: =Forecast_Base!L$4 | H15: =Forecast_Base!L$9 | I15: =Forecast_Base!L$17
A16: =Forecast_Base!C$4 | B16: =Forecast_Base!C$19 | C16: =0 | G16: =Forecast_Base!M$4 | H16: =Forecast_Base!M$9 | I16: =Forecast_Base!M$17
A17: =Forecast_Base!D$4 | B17: =Forecast_Base!D$19 | C17: =0 | G17: =Forecast_Base!N$4 | H17: =Forecast_Base!N$9 | I17: =Forecast_Base!N$17
A18: =Forecast_Base!E$4 | B18: =Forecast_Base!E$19 | C18: =0 | G18: =Forecast_Base!O$4 | H18: =Forecast_Base!O$9 | I18: =Forecast_Base!O$17
A19: =Forecast_Base!F$4 | B19: =Forecast_Base!F$19 | C19: =0 | G19: =Forecast_Base!P$4 | H19: =Forecast_Base!P$9 | I19: =Forecast_Base!P$17
A20: =Forecast_Base!G$4 | B20: =Forecast_Base!G$19 | C20: =0 | G20: =Forecast_Base!Q$4 | H20: =Forecast_Base!Q$9 | I20: =Forecast_Base!Q$17
A21: =Forecast_Base!H$4 | B21: =Forecast_Base!H$19 | C21: =0 | G21: =Forecast_Base!R$4 | H21: =Forecast_Base!R$9 | I21: =Forecast_Base!R$17
A22: =Forecast_Base!I$4 | B22: =Forecast_Base!I$19 | C22: =0 | G22: =Forecast_Base!S$4 | H22: =Forecast_Base!S$9 | I22: =Forecast_Base!S$17
A23: =Forecast_Base!J$4 | B23: =Forecast_Base!J$19 | C23: =0 | G23: =Forecast_Base!T$4 | H23: =Forecast_Base!T$9 | I23: =Forecast_Base!T$17
A24: =Forecast_Base!K$4 | B24: =Forecast_Base!K$19 | C24: =0 | G24: =Forecast_Base!U$4 | H24: =Forecast_Base!U$9 | I24: =Forecast_Base!U$17
A25: =Forecast_Base!L$4 | B25: =Forecast_Base!L$19 | C25: =0 | G25: =Forecast_Base!V$4 | H25: =Forecast_Base!V$9 | I25: =Forecast_Base!V$17
A26: =Forecast_Base!M$4 | B26: =Forecast_Base!M$19 | C26: =0 | G26: =Forecast_Base!W$4 | H26: =Forecast_Base!W$9 | I26: =Forecast_Base!W$17
A27: =Forecast_Base!N$4 | B27: =Forecast_Base!N$19 | C27: =0 | G27: =Forecast_Base!X$4 | H27: =Forecast_Base!X$9 | I27: =Forecast_Base!X$17
A28: =Forecast_Base!O$4 | B28: =Forecast_Base!O$19 | C28: =0 | G28: =Forecast_Base!Y$4 | H28: =Forecast_Base!Y$9 | I28: =Forecast_Base!Y$17
A29: =Forecast_Base!P$4 | B29: =Forecast_Base!P$19 | C29: =0
A30: =Forecast_Base!Q$4 | B30: =Forecast_Base!Q$19 | C30: =0
A31: =Forecast_Base!R$4 | B31: =Forecast_Base!R$19 | C31: =0 | J31: Escenario | K31: EBITDA M12 | L31: Lectura | M31: Precio/h | N31: Churn
A32: =Forecast_Base!S$4 | B32: =Forecast_Base!S$19 | C32: =0 | J32: =Escenarios!A5 | K32: =Escenarios!I5 | L32: =Escenarios!K5 | M32: =Escenarios!B5 | N32: =Escenarios!F5
A33: =Forecast_Base!T$4 | B33: =Forecast_Base!T$19 | C33: =0 | J33: =Escenarios!A6 | K33: =Escenarios!I6 | L33: =Escenarios!K6 | M33: =Escenarios!B6 | N33: =Escenarios!F6
A34: =Forecast_Base!U$4 | B34: =Forecast_Base!U$19 | C34: =0 | J34: =Escenarios!A7 | K34: =Escenarios!I7 | L34: =Escenarios!K7 | M34: =Escenarios!B7 | N34: =Escenarios!F7
A35: =Forecast_Base!V$4 | B35: =Forecast_Base!V$19 | C35: =0
A36: =Forecast_Base!W$4 | B36: =Forecast_Base!W$19 | C36: =0
A37: =Forecast_Base!X$4 | B37: =Forecast_Base!X$19 | C37: =0
A38: =Forecast_Base!Y$4 | B38: =Forecast_Base!Y$19 | C38: =0
A41: Costo | B41: Monto mensual
A42: Pago tutores | B42: =Forecast_Base!M10
A43: Pauta | B43: =Forecast_Base!M15
...

Sheet Supuestos
A1: Centro de Tutorías - Supuestos editables
A2: Las celdas amarillas son inputs. El caso base usa precios y margen definidos en Notion.
A4: Bloque | B4: Variable | C4: Valor | D4: Unidad | E4: Fuente | F4: Notas
A5: Modelo | B5: Tipo de cambio USD/GTQ | C5: 7.63 | D5: Q / USD | E5: S08 | F5: Banguat / referencia de mayo 2026; editable para compras de pauta en USD.
A6: Precios | B6: Precio virtual por hora | C6: 200 | D6: Q/hora | E6: N03 | F6: Precio objetivo definido en Notion.
A7: Precios | B7: Precio presencial por hora | C7: 275 | D7: Q/hora | E7: N03 | F7: Precio objetivo definido en Notion.
A8: Precios | B8: Mix virtual | C8: 0.8 | D8: % de horas | E8: A01 | F8: Supuesto operativo inicial: foco virtual para escalar con menor complejidad.
A9: Precios | B9: Mix presencial | C9: 0.2 | D9: % de horas | E9: A01 | F9: Complemento premium para zonas objetivo.
A10: Costos variables | B10: Pago a tutores | C10: 0.7 | D10: % ingresos | E10: N03 | F10: Distribución Notion: 70% tutor / 30% Centro.
A11: Costos variables | B11: Comisión pagos | C11: 0.03 | D11: % ingresos | E11: A02 | F11: Supuesto para pasarela, transferencias y cobros digitales.
A12: Costos variables | B12: Materiales por hora | C12: 5 | D12: Q/hora | E12: A03 | F12: Plantillas, ejercicios, recursos digitales, seguimiento.
A13: Demanda | B13: Horas por alumno al mes | C13: 6 | D13: horas | E13: A04 | F13: Paquete promedio: 1-2 horas por semana según necesidad.
A14: Demanda | B14: Alumnos nuevos mes 1 | C14: 8 | D14: alumnos | E14: A05 | F14: Ramp-up conservador con pauta y referidos.
A15: Demanda | B15: Crecimiento mensual alumnos nuevos | C15: 0.1 | D15: % | E15: A05 | F15: Mejora de campañas, referidos y alianzas.
A16: Demanda | B16: Churn mensual | C16: 0.08 | D16: % | E16: A06 | F16: Rotación por estacionalidad académica y necesidades puntuales.
... A26: Inversión | B26: Inversión inicial estimada | C26: 24500 | D26: Q | E26: A14 | F26: Detalle en hoja Inversion_Costos.

Sheet Mercado
A1: Análisis de mercado y señales comerciales
A2: Resumen de demanda, competencia, cliente objetivo y canales para Ciudad de Guatemala.
A4: Tema | B4: Insight | C4: Dato / Rango | D4: Implicación | E4: Fuente | F4: Confianza | G4: Acción recomendada | H4: Notas
A5: Segmento | B5: Padres de 30-50 años en zonas 10, 14, 15, 16 y Carretera a El Salvador. | C5: 202.8k-238.6k público estimado | D5: Nicho suficiente para piloto pagado y referidos. | E5: N08 | F5: Alta | G5: Lanzar prueba en Meta + WhatsApp | H5: Dato de segmentación de campaña en Notion.
A6: Necesidad | B6: Refuerzo en matemáticas, estadística, física y materias críticas. | C6: Primaria a primeros años de universidad | D6: Oferta debe agruparse por urgencia: exámenes, nivelación, promedio. | E6: N01/N06 | F6: Alta | G6: Crear paquetes por objetivo | H6: La ansiedad de padres ante notas es el disparador principal.
A7: Precio competitivo | B7: Competidor Tutorías GT cobra Q109 virtual y Q154 presencial. | C7: Q109-Q154/h | D7: El precio objetivo es premium; requiere prueba, seguimiento y evidencia. | E7: N02 | F7: Alta | G7: Justificar con diagnóstico y reportes | H7: No competir solo por precio.
A8: Precio de mercado | B8: Plataformas y anuncios muestran rangos amplios de Q50-Q200/h. | C8: Q80-Q200/h común | D8: Q225 virtual exige posicionamiento de alta calidad. | E8: S02/S04 | F8: Media | G8: Usar paquetes y valor agregado | H8: Los tutores independientes presionan precio a la baja.
A9: Presupuesto hogar | B9: Avatar en Notion estima disposición de pago mensual de USD 100-300, hasta USD 500 intensivo. | C9: Q763-Q2,289 base | D9: Paquetes mensuales de 4, 8 y 12 horas caben en rango. | E9: N05 | F9: Media-Alta | G9: Ofrecer planes mensuales | H9: El precio por hora debe traducirse a progreso visible.
A10: Canales | B10: Google capta intención; Meta y TikTok generan demanda y retargeting. | C10: 50/30/20 sugerido | D10: Mezcla inicial balanceada con aprendizaje rápido. | E10: N04/N07 | F10: Alta | G10: Medir CPL por canal | H10: WhatsApp debe cerrar la venta.
A11: Pauta | B11: Google Ads Guatemala reporta CPC general de Q2.50-Q15 y presupuestos iniciales de Q1,500-Q5,000. | C11: Q1.5k-Q5.0k/mes | D11: Base de Q3.1k/mes es razonable para piloto. | E11: S03 | F11: Media | G11: Probar keywords exactas | H11: El CPL real debe reemplazar el supuesto al mes 1.
A12: Estacionalidad | B12: Picos esperados antes de exámenes, regreso a clases y cierre de año. | C12: Mar-Jun / Sep-Nov | D12: Forecast debe revisarse por calendario académico. | E12: N07/A15 | F12: Media | G12: Campañas por temporada | H12: El modelo usa rampa lineal simplificada.
A13: Diferenciación | B13: Padres valoran seguridad, personalización, flexibilidad y seguimiento. | C13: Deal-makers: resultados medibles | D13: Reportes de progreso sostienen precio y retención. | E13: N05/N06 | F13: Alta | G13: Diseñar reporte post-sesión | H13: Convertir servicio en acompañamiento.
A14: Riesgo | B14: Si el tutor no conecta o no hay resultados, el churn sube. | C14: Churn base 8% mensual | D14: La operación debe controlar calidad desde el inicio. | E14: N06/A06 | F14: Media | G14: Checklist de calidad del tutor | H14: Cambios de tutor y garantías reducen fricción.

Sheet Unit_Economics
A1: Unit economics por hora y por alumno
A2: Calcula margen, contribución y volumen necesario para cubrir costos fijos.
A4: Métrica | B4: Fórmula / Fuente | C4: Valor | D4: Unidad | F4: Paquete | G4: Horas/mes | H4: Precio mensual
A5: Precio ponderado por hora | B5: Virtual/presencial según mix | C5: =Supuestos!C6*Supuestos!C8+Supuestos!C7*Supuestos!C9 | D5: Q/hora | F5: Plan Refuerzo | G5: 4 | H5: =G5*$C$5
A6: Pago tutor por hora | B6: 70% de ingreso | C6: =C5*Supuestos!C10 | D6: Q/hora | F6: Plan Constancia | G6: 8 | H6: =G6*$C$5
A7: Comisión de cobro por hora | B7: 3% de ingreso | C7: =C5*Supuestos!C11 | D7: Q/hora | F7: Plan Intensivo | G7: 12 | H7: =G7*$C$5
A8: Materiales por hora | B8: Input | C8: =Supuestos!C12 | D8: Q/hora
A9: Contribución por hora | B9: Ingreso - variables | C9: =C5-C6-C7-C8 | D9: Q/hora
A10: Margen de contribución | B10: Contribución / ingreso | C10: =C9/C5 | D10: %
A11: Horas por alumno al mes | B11: Input | C11: =Supuestos!C13 | D11: horas
A12: Ingreso mensual por alumno | B12: Precio x horas | C12: =C5*C11 | D12: Q/alumno
A13: Contribución mensual por alumno | B13: Contribución x horas | C13: =C9*C11 | D13: Q/alumno
A14: Costos fijos mensuales base | B14: Operación + pauta | C14: =Inversion_Costos!B23 | D14: Q/mes
A15: Horas break-even mensual | B15: Fijos / contribución hora | C15: =C14/C9 | D15: horas
A16: Alumnos break-even mensual | B16: Horas BE / horas alumno | C16: =C15/C11 | D16: alumnos activos
A17: Leads necesarios por alumno | B17: 1 / conversión | C17: =1/Supuestos!C18 | D17: leads
A18: CAC estimado | B18: CPL / conversión | C18: =Supuestos!C17/Supuestos!C18 | D18: Q/cliente
A19: Payback CAC | B19: CAC / contribución alumno | C19: =C18/C13 | D19: meses

Sheet Forecast_Base
A1: Forecast mensual - Caso base
A2: Horizonte mayo 2026 a abril 2028. Fórmulas editables y ligadas a Supuestos.
A4: Métrica | B4: may 26 | C4: jun 26 | D4: jul 26 | E4: ago 26 | F4: sept 26 | G4: oct 26 | H4: nov 26 | I4: dic 26 | J4: ene 27 | K4: feb 27 | L4: mar 27 | M4: abr 27 | N4: may 27 | O4: jun 27 | P4: jul 27 | Q4: ago 27 | R4: sept 27 | S4: oct 27 | T4: nov 27 | U4: dic 27 | V4: ene 28 | W4: feb 28 | X4: mar 28 | Y4: abr 28
A5: Alumnos nuevos | B5: =Supuestos!C14 | C5: =B5*(1+Supuestos!C15) | D5: =C5*(1+Supuestos!C15) | E5: =D5*(1+Supuestos!C15) | F5: =E5*(1+Supuestos!C15) | G5: =F5*(1+Supuestos!C15) | H5: =G5*(1+Supuestos!C15) | I5: =H5*(1+Supuestos!C15) | J5: =I5*(1+Supuestos!C15) | K5: =J5*(1+Supuestos!C15) | L5: =K5*(1+Supuestos!C15) | M5: =L5*(1+Supuestos!C15) | N5: =M5*(1+Supuestos!C15) | O5: =N5*(1+Supuestos!C15) | P5: =O5*(1+Supuestos!C15) | Q5: =P5*(1+Supuestos!C15) | R5: =Q5*(1+Supuestos!C15) | S5: =R5*(1+Supuestos!C15) | T5: =S5*(1+Supuestos!C15) | U5: =T5*(1+Supuestos!C15) | V5: =U5*(1+Supuestos!C15) | W5: =V5*(1+Supuestos!C15) | X5: =W5*(1+Supuestos!C15) | Y5: =X5*(1+Supuestos!C15)
A6: Alumnos activos | B6: =B5 | C6: =B6*(1-Supuestos!C16)+C5 | D6: =C6*(1-Supuestos!C16)+D5 | E6: =D6*(1-Supuestos!C16)+E5 | F6: =E6*(1-Supuestos!C16)+F5 | G6: =F6*(1-Supuestos!C16)+G5 | H6: =G6*(1-Supuestos!C16)+H5 | I6: =H6*(1-Supuestos!C16)+I5 | J6: =I6*(1-Supuestos!C16)+J5 | K6: =J6*(1-Supuestos!C16)+K5 | L6: =K6*(1-Supuestos!C16)+L5 | M6: =L6*(1-Supuestos!C16)+M5 | N6: =M6*(1-Supuestos!C16)+N5 | O6: =N6*(1-Supuestos!C16)+O5 | P6: =O6*(1-Supuestos!C16)+P5 | Q6: =P6*(1-Supuestos!C16)+Q5 | R6: =Q6*(1-Supuestos!C16)+R5 | S6: =R6*(1-Supuestos!C16)+S5 | T6: =S6*(1-Supuestos!C16)+T5 | U6: =T6*(1-Supuestos!C16)+U5 | V6: =U6*(1-Supuestos!C16)+V5 | W6: =V6*(1-Supuestos!C16)+W5 | X6: =W6*(1-Supuestos!C16)+X5 | Y6: =X6*(1-Supuestos!C16)+Y5
A7: Horas vendidas | B7: =B6*Supuestos!C13 | C7: =C6*Supuestos!C13 | D7: =D6*Supuestos!C13 | E7: =E6*Supuestos!C13 | F7: =F6*Supuestos!C13 | G7: =G6*Supuestos!C13 | H7: =H6*Supuestos!C13 | I7: =I6*Supuestos!C13 | J7: =J6*Supuestos!C13 | K7: =K6*Supuestos!C13 | L7: =L6*Supuestos!C13 | M7: =M6*Supuestos!C13 | N7: =N6*Supuestos!C13 | O7: =O6*Supuestos!C13 | P7: =P6*Supuestos!C13 | Q7: =Q6*Supuestos!C13 | R7: =R6*Supuestos!C13 | S7: =S6*Supuestos!C13 | T7: =T6*Supuestos!C13 | U7: =U6*Supuestos!C13 | V7: =V6*Supuestos!C13 | W7: =W6*Supuestos!C13 | X7: =X6*Supuestos!C13 | Y7: =Y6*Supuestos!C13
A8: Precio ponderado por hora | B8: =Unit_Economics!C5 | C8: =Unit_Economics!C5 | D8: =Unit_Economics!C5 | E8: =Unit_Economics!C5 | F8: =Unit_Economics!C5 | G8: =Unit_Economics!C5 | H8: =Unit_Economics!C5 | I8: =Unit_Economics!C5 | J8: =Unit_Economics!C5 | K8: =Unit_Economics!C5 | L8: =Unit_Economics!C5 | M8: =Unit_Economics!C5 | N8: =Unit_Economics!C5 | O8: =Unit_Economics!C5 | P8: =Unit_Economics!C5 | Q8: =Unit_Economics!C5 | R8: =Unit_Economics!C5 | S8: =Unit_Economics!C5 | T8: =Unit_Economics!C5 | U8: =Unit_Economics!C5 | V8: =Unit_Economics!C5 | W8: =Unit_Economics!C5 | X8: =Unit_Economics!C5 | Y8: =Unit_Economics!C5
A9: Ingresos | B9: =B7*B8 | C9: =C7*C8 | D9: =D7*D8 | E9: =E7*E8 | F9: =F7*F8 | G9: =G7*G8 | H9: =H7*H8 | I9: =I7*I8 | ... Y9: =Y7*Y8
A10: Pago a tutores | B10: =B9*Supuestos!C10 | C10: =C9*Supuestos!C10 | D10: =D9*Supuestos!C10 | E10: =E9*Supuestos!C10 | F10: =F9*Supuestos!C10 | G10: =G9*Supuestos!C10 | H10: =H9*Supuestos!C10 | I10: =I9*Supuestos!C10 | J10: =J9*Supuestos!C10 | K10: =K9*Supuestos!C10 | L10: =L9*Supuestos!C10 | M10: =M9*Supuestos!C10 | N10: =N9*Supuestos!C10 | O10: =O9*Supuestos!C10 | P10: =P9*Supuestos!C10 | Q10: =Q9*Supuestos!C10 | R10: =R9*Supuestos!C10 | S10: =S9*Supuestos!C10 | T10: =T9*Supuestos!C10 | U10: =U9*Supuestos!C10 | V10: =V9*Supuestos!C10 | W10: =W9*Supuestos!C10 | X10: =X9*Supuestos!C10 | Y10: =Y9*Supuestos!C10
A11: Comisiones de pago | B11: =B9*Supuestos!C11 | C11: =C9*Supuestos!C11 | D11: =D9*Supuestos!C11 | E11: =E9*Supuestos!C11 | F11: =F9*Supuestos!C11 | G11: =G9*Supuestos!C11 | H11: =H9*Supuestos!C11 | I11: =I9*Supuestos!C11 | J11: =J9*Supuestos!C11 | K11: =K9*Supuestos!C11 | L11: =L9*Supuestos!C11 | M11: =M9*Supuestos!C11 | N11: =N9*Supuestos!C11 | O11: =O9*Supuestos!C11 | P11: =P9*Supuestos!C11 | Q11: =Q9*Supuestos!C11 | R11: =R9*Supuestos!C11 | S11: =S9*Supuestos!C11 | T11: =T9*Supuestos!C11 | U11: =U9*Supuestos!C11 | V11: =V9*Supuestos!C11 | W11: =W9*Supuestos!C11 | X11: =X9*Supuestos!C11 | Y11: =Y9*Supuestos!C11
A12: Materiales | B12: =B7*Supuestos!C12 | C12: =C7*Supuestos!C12 | D12: =D7*Supuestos!C12 | E12: =E7*Supuestos!C12 | F12: =F7*Supuestos!C12 | G12: =G7*Supuestos!C12 | H12: =H7*Supuestos!C12 | I12: =I7*Supuestos!C12 | J12: =J7*Supuestos!C12 | K12: =K7*Supuestos!C12 | L12: =L7*Supuestos!C12 | M12: =M7*Supuestos!C12 | N12: =N7*Supuestos!C12 | O12: =O7*Supuestos!C12 | P12: =P7*Supuestos!C12 | Q12: =Q7*Supuestos!C12 | R12: =R7*Supuestos!C12 | S12: =S7*Supuestos!C12 | T12: =T7*Supuestos!C12 | U12: =U7*Supuestos!C12 | V12: =V7*Supuestos!C12 | W12: =W7*Supuestos!C12 | X12: =X7*Supuestos!C12 | Y12: =Y7*Supuestos!C12
A13: Margen bruto / contribución | B13: =B9-B10-B11-B12 | C13: =C9-C10-C11-C12 | D13: =D9-D10-D11-D12 | E13: =E9-E10-E11-E12 | F13: =F9-F10-F11-F12 | G13: =G9-G10-G11-G12 | H13: =H9-H10-H11-H12 | I13: =I9-I10-I11-I12 | ... Y13: =Y9-Y10-Y11-Y12
A14: Margen contribución % | B14: =IFERROR(B13/B9,0) | C14: =IFERROR(C13/C9,0) | D14: =IFERROR(D13/D9,0) | E14: =IFERROR(E13/E9,0) | F14: =IFERROR(F13/F9,0) | G14: =IFERROR(G13/G9,0) | H14: =IFERROR(H13/H9,0) | I14: =IFERROR(I13/I9,0) | ... Y14: =IFERROR(Y13/Y9,0)
A15: Pauta | B15: =Supuestos!C17*Supuestos!C5*(1+Supuestos!C18)^INT(0/6) | C15: =Supuestos!C17*Supuestos!C5*(1+Supuestos!C18)^INT(1/6) | D15: =Supuestos!C17*Supuestos!C5*(1+Supuestos!C18)^INT(2/6) | E15: =Supuestos!C17*Supuestos!C5*(1+Supuestos!C18)^INT(3/6) | F15: =Supuestos!C17*Supuestos!C5*(1+Supuestos!C18)^INT(4/6) | G15: =Supuestos!C17*Supuestos!C5*(1+Supuestos!C18)^INT(5/6) | H15: =Supuestos!C17*Supuestos!C5*(1+Supuestos!C18)^INT(6/6) | I15: =Supuestos!C17*Supuestos!C5*(1+Supuestos!C18)^INT(7/6) | J15: =Supuestos!C17*Supuestos!C5*(1+Supuestos!C18)^INT(8/6) | K15: =Supuestos!C17*Supuestos!C5*(1+Supuestos!C18)^INT(9/6) | L15: =Supuestos!C17*Supuestos!C5*(1+Supuestos!C18)^INT(10/6) | M15: =Supuestos!C17*Supuestos!C5*(1+Supuestos!C18)^INT(11/6) | N15: =Supuestos!C17*Supuestos!C5*(1+Supuestos!C18)^INT(12/6) | O15: =Supuestos!C17*Supuestos!C5*(1+Supuestos!C18)^INT(13/6) | P15: =Supuestos!C17*Supuestos!C5*(1+Supuestos!C18)^INT(14/6) | Q15: =Supuestos!C17*Supuestos!C5*(1+Supuestos!C18)^INT(15/6) | R15: =Supuestos!C17*Supuestos!C5*(1+Supuestos!C18)^INT(16/6) | S15: =Supuestos!C17*Supuestos!C5*(1+Supuestos!C18)^INT(17/6) | T15: =Supuestos!C17*Supuestos!C5*(1+Supuestos!C18)^INT(18/6) | U15: =Supuestos!C17*Supuestos!C5*(1+Supuestos!C18)^INT(19/6) | V15: =Supuestos!C17*Supuestos!C5*(1+Supuestos!C18)^INT(20/6) | W15: =Supuestos!C17*Supuestos!C5*(1+Supuestos!C18)^INT(21/6) | X15: =Supuestos!C17*Supuestos!C5*(1+Supuestos!C18)^INT(22/6) | Y15: =Supuestos!C17*Supuestos!C5*(1+Supuestos!C18)^INT(23/6)
A16: Otros costos fijos | B16: =Inversion_Costos!B21 | C16: =Inversion_Costos!B21 | D16: =Inversion_Costos!B21 | E16: =Inversion_Costos!B21 | F16: =Inversion_Costos!B21 | G16: =Inversion_Costos!B21 | H16: =Inversion_Costos!B21 | I16: =Inversion_Costos!B21 | J16: =Inversion_Costos!B21 | K16: =Inversion_Costos!B21 | L16: =Inversion_Costos!B21 | M16: =Inversion_Costos!B21 | N16: =Inversion_Costos!B21 | O16: =Inversion_Costos!B21 | P16: =Inversion_Costos!B21 | Q16: =Inversion_Costos!B21 | R16: =Inversion_Costos!B21 | S16: =Inversion_Costos!B21 | T16: =Inversion_Costos!B21 | U16: =Inversion_Costos!B21 | V16: =Inversion_Costos!B21 | W16: =Inversion_Costos!B21 | X16: =Inversion_Costos!B21 | Y16: =Inversion_Costos!B21
A17: EBITDA | B17: =B13-B15-B16 | C17: =C13-C15-C16 | D17: =D13-D15-D16 | E17: =E13-E15-E16 | F17: =F13-F15-F16 | G17: =G13-G15-G16 | H17: =H13-H15-H16 | I17: =I13-I15-I16 | ... Y17: =Y13-Y15-Y16
A18: Margen EBITDA | B18: =IFERROR(B17/B9,0) | C18: =IFERROR(C17/C9,0) | D18: =IFERROR(D17/D9,0) | E18: =IFERROR(E17/E9,0) | F18: =IFERROR(F17/F9,0) | G18: =IFERROR(G17/G9,0) | H18: =IFERROR(H17/H9,0) | I18: =IFERROR(I17/I9,0) | ... Y18: =IFERROR(Y17/Y9,0)
A19: Flujo acumulado post-inversión | B19: =-Supuestos!C24+B17 | C19: =B19+C17 | D19: =C19+D17 | E19: =D19+E17 | F19: =E19+F17 | G19: =F19+G17 | H19: =G19+H17 | I19: =H19+I17 | J19: =I19+J17 | ... Y19: =X19+Y17
A20: Leads estimados | B20: =B5/Supuestos!C18 | C20: =C5/Supuestos!C18 | D20: =D5/Supuestos!C18 | E20: =E5/Supuestos!C18 | F20: =F5/Supuestos!C18 | G20: =G5/Supuestos!C18 | H20: =H5/Supuestos!C18 | I20: =I5/Supuestos!C18 | J20: =J5/Supuestos!C18 | K20: =K5/Supuestos!C18 | L20: =L5/Supuestos!C18 | M20: =M5/Supuestos!C18 | N20: =N5/Supuestos!C18 | O20: =O5/Supuestos!C18 | P20: =P5/Supuestos!C18 | Q20: =Q5/Supuestos!C18 | R20: =R5/Supuestos!C18 | S20: =S5/Supuestos!C18 | T20: =T5/Supuestos!C18 | U20: =U5/Supuestos!C18 | V20: =V5/Supuestos!C18 | W20: =W5/Supuestos!C18 | X20: =X5/Supuestos!C18 | Y20: =Y5/Supuestos!C18
A21: CAC estimado | B21: =Unit_Economics!C18 | C21: =Unit_Economics!C18 | D21: =Unit_Economics!C18 | E21: =Unit_Economics!C18 | F21: =Unit_Economics!C18 | G21: =Unit_Economics!C18 | H21: =Unit_Economics!C18 | I21: =Unit_Economics!C18 | J21: =Unit_Economics!C18 | K21: =Unit_Economics!C18 | L21: =Unit_Economics!C18 | M21: =Unit_Economics!C18 | N21: =Unit_Economics!C18 | O21: =Unit_Economics!C18 | P21: =Unit_Economics!C18 | Q21: =Unit_Economics!C18 | R21: =Unit_Economics!C18 | S21: =Unit_Economics!C18 | T21: =Unit_Economics!C18 | U21: =Unit_Economics!C18 | V21: =Unit_Economics!C18 | W21: =Unit_Economics!C18 | X21: =Unit_Economics!C18 | Y21: =Unit_Economics!C18

Sheet Escenarios
A1: Escenarios y sensibilidad
A2: Compara comportamiento financiero con distintos niveles de tracción, precio, churn y pauta.
A4: Escenario | B4: Precio/h | C4: Horas/alumno | D4: Nuevos M1 | E4: Crec. nuevos | F4: Churn | G4: Pauta USD | H4: Fijos Q | I4: EBITDA M12 | J4: Payback | K4: Lectura
A5: Conservador | B5: 210 | C5: 4 | D5: 5 | E5: 0.05 | F5: 0.12 | G5: 250 | H5: 5200 | I5: =(IF(ABS(1-((1+E5)/(1-F5)))<0.0001,D5*12*(1-F5)^11,D5*(1-F5)^11*(1-((1+E5)/(1-F5))^12)/(1-((1+E5)/(1-F5)))))*C5*B5*(1-Supuestos!C10-Supuestos!C11)-(IF(ABS(1-((1+E5)/(1-F5)))<0.0001,D5*12*(1-F5)^11,D5*(1-F5)^11*(1-((1+E5)/(1-F5))^12)/(1-((1+E5)/(1-F5)))))*C5*Supuestos!C12-G5*Supuestos!C5-H5 | J5: =IF(I5<=0,"No recupera en 12m","Ver forecast") | K5: Sirve si la conversión tarda y se compite más por precio.
A6: Base | B6: =Unit_Economics!C5 | C6: =Supuestos!C13 | D6: =Supuestos!C14 | E6: =Supuestos!C15 | F6: =Supuestos!C16 | G6: =Supuestos!C17 | H6: =Inversion_Costos!B21 | I6: =Forecast_Base!M17 | J6: =Resumen!B8 | K6: Caso recomendado: premium moderado, enfoque virtual y seguimiento.
A7: Acelerado | B7: 250 | C7: 8 | D7: 12 | E7: 0.15 | F7: 0.06 | G7: 600 | H7: 7500 | I7: =(IF(ABS(1-((1+E7)/(1-F7)))<0.0001,D7*12*(1-F7)^11,D7*(1-F7)^11*(1-((1+E7)/(1-F7))^12)/(1-((1+E7)/(1-F7)))))*C7*B7*(1-Supuestos!C10-Supuestos!C11)-(IF(ABS(1-((1+E7)/(1-F7)))<0.0001,D7*12*(1-F7)^11,D7*(1-F7)^11*(1-((1+E7)/(1-F7))^12)/(1-((1+E7)/(1-F7)))))*C7*Supuestos!C12-G7*Supuestos!C5-H7 | J7: =IF(I7<=0,"No recupera en 12m","<12 meses probable") | K7: Requiere fuerte ejecución comercial y calidad operativa.
A10: Sensibilidad BE alumnos | B10: Precio/h Q200 | C10: Q225 | D10: Q250 | E10: Q275 | F10: Notas
A11: Horas/alumno 4 | B11: =ROUND(Unit_Economics!C14/((200*(1-Supuestos!C10-Supuestos!C11)-Supuestos!C12)*4),1) | C11: =ROUND(Unit_Economics!C14/((225*(1-Supuestos!C10-Supuestos!C11)-Supuestos!C12)*4),1) | D11: =ROUND(Unit_Economics!C14/((250*(1-Supuestos!C10-Supuestos!C11)-Supuestos!C12)*4),1) | E11: =ROUND(Unit_Economics!C14/((275*(1-Supuestos!C10-Supuestos!C11)-Supuestos!C12)*4),1) | F11: Alumnos activos necesarios
A12: Horas/alumno 6 | B12: =ROUND(Unit_Economics!C14/((200*(1-Supuestos!C10-Supuestos!C11)-Supuestos!C12)*6),1) | C12: =ROUND(Unit_Economics!C14/((225*(1-Supuestos!C10-Supuestos!C11)-Supuestos!C12)*6),1) | D12: =ROUND(Unit_Economics!C14/((250*(1-Supuestos!C10-Supuestos!C11)-Supuestos!C12)*6),1) | E12: =ROUND(Unit_Economics!C14/((275*(1-Supuestos!C10-Supuestos!C11)-Supuestos!C12)*6),1) | F12: Caso base alrededor de esta fila
A13: Horas/alumno 8 | B13: =ROUND(Unit_Economics!C14/((200*(1-Supuestos!C10-Supuestos!C11)-Supuestos!C12)*8),1) | C13: =ROUND(Unit_Economics!C14/((225*(1-Supuestos!C10-Supuestos!C11)-Supuestos!C12)*8),1) | D13: =ROUND(Unit_Economics!C14/((250*(1-Supuestos!C10-Supuestos!C11)-Supuestos!C12)*8),1) | E13: =ROUND(Unit_Economics!C14/((275*(1-Supuestos!C10-Supuestos!C11)-Supuestos!C12)*8),1) | F13: Más horas por alumno mejora rentabilidad
A14: Horas/alumno 12 | B14: =ROUND(Unit_Economics!C14/((200*(1-Supuestos!C10-Supuestos!C11)-Supuestos!C12)*12),1) | C14: =ROUND(Unit_Economics!C14/((225*(1-Supuestos!C10-Supuestos!C11)-Supuestos!C12)*12),1) | D14: =ROUND(Unit_Economics!C14/((250*(1-Supuestos!C10-Supuestos!C11)-Supuestos!C12)*12),1) | E14: =ROUND(Unit_Economics!C14/((275*(1-Supuestos!C10-Supuestos!C11)-Supuestos!C12)*12),1) | F14: Paquetes intensivos bajan BE

Sheet Inversion_Costos
A1: Inversión inicial y estructura de costos
A2: Estimación práctica para lanzar, operar y aprender durante los primeros meses.
A4: Categoría | B4: Tipo | C4: Monto | D4: Unidad | E4: Momento | F4: Necesidad | G4: Fuente | H4: Notas
A5: Landing page + dominio + hosting | B5: Inicial | C5: 5000 | D5: Q | E5: Mes 0 | F5: Alta | G5: A14 | H5: Página de venta con WhatsApp, tracking y formularios.
A6: Branding y creatividades iniciales | B6: Inicial | C6: 3000 | D6: Q | E6: Mes 0 | F6: Alta | G6: A14 | H6: Identidad, plantillas, anuncios, carruseles.
A7: Pauta de prueba inicial | B7: Inicial | C7: 4000 | D7: Q | E7: Mes 0-1 | F7: Alta | G7: N04 | H7: Validar mensajes, audiencias y CPL.
A8: Reclutamiento y capacitación tutores | B8: Inicial | C8: 2500 | D8: Q | E8: Mes 0 | F8: Alta | G8: A14 | H8: Guías, scripts, rúbricas y onboarding.
A9: Setup legal/contable/pagos | B9: Inicial | C9: 2000 | D9: Q | E9: Mes 0 | F9: Media | G9: A14 | H9: Facturación, contratos, términos, métodos de cobro.
A10: Equipo demostrativo / pizarra digital | B10: Inicial | C10: 5000 | D10: Q | E10: Mes 0 | F10: Media | G10: N09 | H10: iPad/tablet, stylus o herramienta equivalente para demos.
A11: Contingencia de lanzamiento | B11: Inicial | C11: 3000 | D11: Q | E11: Mes 0 | F11: Media | G11: A14 | H11: Buffer para ajustes no previstos.
A12: Coordinación / administración | B12: Fijo mensual | C12: 3000 | D12: Q/mes | E12: Mensual | F12: Alta | G12: A09 | H12: Agenda, servicio al cliente y seguimiento.
A13: Software y plataformas | B13: Fijo mensual | C13: 600 | D13: Q/mes | E13: Mensual | F13: Alta | G13: A10 | H13: Herramientas de clase y operación.
A14: Contenido / diseño | B14: Fijo mensual | C14: 1200 | D14: Q/mes | E14: Mensual | F14: Media | G14: A11 | H14: Producción continua para redes.
A15: Contabilidad / legal | B15: Fijo mensual | C15: 500 | D15: Q/mes | E15: Mensual | F15: Media | G15: A12 | H15: Cumplimiento básico.
A16: Misceláneos | B16: Fijo mensual | C16: 500 | D16: Q/mes | E16: Mensual | F16: Media | G16: A13 | H16: Reserva operativa menor.
A17: Pauta base | B17: Fijo mensual | C17: 3052 | D17: Q/mes | E17: Mensual | F17: Alta | G17: N04 | H17: USD 400 x Q7.63.
A19: Resumen | B19: Monto
A20: Inversión inicial total | B20: =SUMIF(B5:B17,"Inicial",C5:C17)
A21: Costos fijos mensuales sin pauta | B21: =SUMIFS(C5:C17,B5:B17,"Fijo mensual",A5:A17,"<>Pauta base")
A22: Pauta mensual base | B22: =SUMIF(A5:A17,"Pauta base",C5:C17)
A23: Costos fijos mensuales total | B23: =B21+B22
A24: Capital recomendado para iniciar | B24: =B20+B23*2

Sheet Fuentes_Checks
A1: Fuentes, notas y checks del modelo
A2: Incluye documentación Notion, fuentes externas y validaciones de consistencia.
A4: ID | B4: Dato / supuesto | C4: Valor | D4: Fecha / periodo | E4: Fuente | F4: Tipo | G4: Confianza | H4: Notas
A5: N01 | B5: Inicio del espacio: niveles atendidos | C5: Primaria, secundaria, diversificado, universidad inicial | D5: 2025-01-11 | E5: Notion: Inicio del espacio de Centro de Tutorías | F5: Interna | G5: Alta | H5: Define alcance del negocio.
A6: N02 | B6: Competidor Tutorías GT | C6: Q109 virtual / Q154 presencial | D6: 2025-01-11 | E6: Notion: Investigación de mercado | F6: Interna | G6: Alta | H6: Respuesta registrada de competidor.
A7: N03 | B7: Precio objetivo y reparto | C7: Q225 virtual, Q275 presencial, 70% tutor / 30% centro | D7: 2025-01-09 | E7: Notion: Definir estrategia de precios | F7: Interna | G7: Alta | H7: Base de unit economics.
A8: N04 | B8: Presupuesto marketing sugerido | C8: USD 300-500/mes | D8: 2025-01-05 | E8: Notion: Plan de Marketing | F8: Interna | G8: Alta | H8: Base usa USD 400/mes.
A9: N05 | B9: Avatar y sensibilidad económica | C9: USD 100-300/mes; techo USD 500 | D9: 2025-01-09 | E9: Notion: Avatar Cliente 360 | F9: Interna | G9: Media-Alta | H9: Debe validarse con ventas reales.
A10: N06 | B10: Objeciones principales | C10: Costo, calidad tutor, resultados, seguridad | D10: 2025-01-09 | E10: Notion: Objeciones | F10: Interna | G10: Alta | H10: Influye en mensajes y retención.
A11: N07 | B11: Canales y plan de marketing | C11: Meta, Google, TikTok; 50/30/20 | D11: 2025-01-09 | E11: Notion: Estrategia de Marketing | F11: Interna | G11: Alta | H11: Guía de mezcla de pauta.
A12: N08 | B12: Segmentación de campaña | C12: Zonas 10,14,15,16,CES; 30-50 años; 202.8k-238.6k | D12: 2025-01-11 | E12: Notion: Lanzamiento campañas publicitarias | F12: Interna | G12: Alta | H12: Público inicial para test.
A13: N09 | B13: Recursos clave | C13: Zoom/iPads/pizarras interactivas | D13: 2025-01-05 | E13: Notion: Business Model Canvas | F13: Interna | G13: Alta | H13: Soporta inversión de equipo demo.
A14: S01 | B14: Matrícula oficial Guatemala | C14: Más de 3.0M estudiantes sector oficial | D14: 2024 | E14: Agencia Guatemalteca de Noticias / Mineduc | F14: Externa | G14: Media | H14: Demanda educativa amplia; no equivale a mercado pagador.
A15: S02 | B15: Rango tutorías Superprof Guatemala | C15: Q80-Q200/h habitual | D15: 2026 | E15: Superprof Guatemala | F15: Externa | G15: Media | H15: Oferta independiente comparable.
... A22: A06 | B22: Churn mensual | C22: 8% | D22: Modelo | E22: Supuesto analista | F22: Supuesto | G22: Media | H22: Medir por cohortes.
A25: Check | B25: Actual | C25: Esperado | D25: Diferencia | E25: Tolerancia | F25: Estado
A26: Mix suma 100% | B26: =Supuestos!C8+Supuestos!C9 | C26: 1 | D26: =B26-C26 | E26: 0.0001 | F26: =IF(ABS(D26)<=E26,"OK","Revisar")
A27: Precio ponderado positivo | B27: =Unit_Economics!C5 | C27: >0 | F27: =IF(B27>0,"OK","Revisar")
A28: Contribución positiva | B28: =Unit_Economics!C9 | C28: >0 | F28: =IF(B28>0,"OK","Revisar")
A29: Forecast mes 12 revenue | B29: =Forecast_Base!M9 | C29: >0 | F29: =IF(B29>0,"OK","Revisar")
A30: EBITDA se vuelve positivo | B30: =COUNTIF(Forecast_Base!B17:Y17,">0") | C30: >0 meses | F30: =IF(B30>0,"OK","Revisar")
A31: Flujo acumulado recupera inversión | B31: =COUNTIF(Forecast_Base!B19:Y19,">0") | C31: >=0 meses | F31: =IF(B31>0,"OK - en horizonte","No en horizonte")
